Workbook

Sheet ターゲット10社リスト
A1: ターゲット法人10社リスト（90日WBS M1／W2）
A2: 会社名を入れると『優先度スコア』『判定』が自動計算されます。選定基準・配点は右のシート参照。※社名・数値は記入例。実データに置換してください。
A3: No. | B3: 会社／店舗名 | C3: 業種（Tier1） | D3: 所在地 | E3: 規模 (人数) | F3: 決裁者 (役割) | G3: 即決度 | H3: 離職・採用 の痛み | I3: 長期雇用 育成志向 | J3: スポット ワーク依存 | K3: 接点（経路） | L3: 優先度 スコア | M3: 判定 | N3: ステータス | O3: 次アクション | P3: メモ
A4: 例 | B4: （例）海辺のカフェ A店 | C4: 飲食・カフェ | D4: 神奈川・鎌倉 | E4: 8 | F4: オーナー | G4: 即決可（トップ即決） | H4: 高（顕在） | I4: 強い | J4: なし | K4: 紹介（トップ直） | L4: =IF($B4="","",IFERROR(VLOOKUP($C4,'選定基準・配点'!$B$21:$C$28,2,FALSE),0)+IF($E4="",0,IF(AND($E4>=5,$E4<=15),2,IF(OR(AND($E4>=3,$E4<=4),AND($E4>=16,$E4<=25)),1,0)))+IFERROR(VLOOKUP($G4,'選定基準・配点'!$B$30:$C$32,2,FALSE),0)+IFERROR(VLOOKUP($H4,'選定基準・配点'!$B$34:$C$36,2,FALSE),0)+IFERROR(VLOOKUP($I4,'選定基準・配点'!$B$38:$C$41,2,FALSE),0)+IFERROR(VLOOKUP($K4,'選定基準・配点'!$B$43:$C$48,2,FALSE),0)) | M4: =IF($B4="","",IF($J4="恒常依存（除外）","除外",IF($L4>=12,"優先",IF($L4>=8,"要検討","見送り候補")))) | N4: 未接触 | O4: 紹介者経由でオーナーに1回受診を打診 | P4: 接客中心・繁忙期の定着に課題
A5: 例 | B5: （例）Bダイニング（多店舗） | C5: 飲食・カフェ | D5: 東京・都内 | E5: 40 | F5: エリアマネージャー | G5: 稟議必要 | H5: 中 | I5: 不明 | J5: 恒常依存（除外） | K5: 直接（コールド） | L5: =IF($B5="","",IFERROR(VLOOKUP($C5,'選定基準・配点'!$B$21:$C$28,2,FALSE),0)+IF($E5="",0,IF(AND($E5>=5,$E5<=15),2,IF(OR(AND($E5>=3,$E5<=4),AND($E5>=16,$E5<=25)),1,0)))+IFERROR(VLOOKUP($G5,'選定基準・配点'!$B$30:$C$32,2,FALSE),0)+IFERROR(VLOOKUP($H5,'選定基準・配点'!$B$34:$C$36,2,FALSE),0)+IFERROR(VLOOKUP($I5,'選定基準・配点'!$B$38:$C$41,2,FALSE),0)+IFERROR(VLOOKUP($K5,'選定基準・配点'!$B$43:$C$48,2,FALSE),0)) | M5: =IF($B5="","",IF($J5="恒常依存（除外）","除外",IF($L5>=12,"優先",IF($L5>=8,"要検討","見送り候補")))) | N5: 見送り | O5: 初期リストからは外す（スポットワーク恒常依存） | P5: 除外条件に該当の例
A6: 1 | L6: =IF($B6="","",IFERROR(VLOOKUP($C6,'選定基準・配点'!$B$21:$C$28,2,FALSE),0)+IF($E6="",0,IF(AND($E6>=5,$E6<=15),2,IF(OR(AND($E6>=3,$E6<=4),AND($E6>=16,$E6<=25)),1,0)))+IFERROR(VLOOKUP($G6,'選定基準・配点'!$B$30:$C$32,2,FALSE),0)+IFERROR(VLOOKUP($H6,'選定基準・配点'!$B$34:$C$36,2,FALSE),0)+IFERROR(VLOOKUP($I6,'選定基準・配点'!$B$38:$C$41,2,FALSE),0)+IFERROR(VLOOKUP($K6,'選定基準・配点'!$B$43:$C$48,2,FALSE),0)) | M6: =IF($B6="","",IF($J6="恒常依存（除外）","除外",IF($L6>=12,"優先",IF($L6>=8,"要検討","見送り候補"))))
A7: 2 | L7: =IF($B7="","",IFERROR(VLOOKUP($C7,'選定基準・配点'!$B$21:$C$28,2,FALSE),0)+IF($E7="",0,IF(AND($E7>=5,$E7<=15),2,IF(OR(AND($E7>=3,$E7<=4),AND($E7>=16,$E7<=25)),1,0)))+IFERROR(VLOOKUP($G7,'選定基準・配点'!$B$30:$C$32,2,FALSE),0)+IFERROR(VLOOKUP($H7,'選定基準・配点'!$B$34:$C$36,2,FALSE),0)+IFERROR(VLOOKUP($I7,'選定基準・配点'!$B$38:$C$41,2,FALSE),0)+IFERROR(VLOOKUP($K7,'選定基準・配点'!$B$43:$C$48,2,FALSE),0)) | M7: =IF($B7="","",IF($J7="恒常依存（除外）","除外",IF($L7>=12,"優先",IF($L7>=8,"要検討","見送り候補"))))
A8: 3 | L8: =IF($B8="","",IFERROR(VLOOKUP($C8,'選定基準・配点'!$B$21:$C$28,2,FALSE),0)+IF($E8="",0,IF(AND($E8>=5,$E8<=15),2,IF(OR(AND($E8>=3,$E8<=4),AND($E8>=16,$E8<=25)),1,0)))+IFERROR(VLOOKUP($G8,'選定基準・配点'!$B$30:$C$32,2,FALSE),0)+IFERROR(VLOOKUP($H8,'選定基準・配点'!$B$34:$C$36,2,FALSE),0)+IFERROR(VLOOKUP($I8,'選定基準・配点'!$B$38:$C$41,2,FALSE),0)+IFERROR(VLOOKUP($K8,'選定基準・配点'!$B$43:$C$48,2,FALSE),0)) | M8: =IF($B8="","",IF($J8="恒常依存（除外）","除外",IF($L8>=12,"優先",IF($L8>=8,"要検討","見送り候補"))))
A9: 4 | L9: =IF($B9="","",IFERROR(VLOOKUP($C9,'選定基準・配点'!$B$21:$C$28,2,FALSE),0)+IF($E9="",0,IF(AND($E9>=5,$E9<=15),2,IF(OR(AND($E9>=3,$E9<=4),AND($E9>=16,$E9<=25)),1,0)))+IFERROR(VLOOKUP($G9,'選定基準・配点'!$B$30:$C$32,2,FALSE),0)+IFERROR(VLOOKUP($H9,'選定基準・配点'!$B$34:$C$36,2,FALSE),0)+IFERROR(VLOOKUP($I9,'選定基準・配点'!$B$38:$C$41,2,FALSE),0)+IFERROR(VLOOKUP($K9,'選定基準・配点'!$B$43:$C$48,2,FALSE),0)) | M9: =IF($B9="","",IF($J9="恒常依存（除外）","除外",IF($L9>=12,"優先",IF($L9>=8,"要検討","見送り候補"))))
A10: 5 | L10: =IF($B10="","",IFERROR(VLOOKUP($C10,'選定基準・配点'!$B$21:$C$28,2,FALSE),0)+IF($E10="",0,IF(AND($E10>=5,$E10<=15),2,IF(OR(AND($E10>=3,$E10<=4),AND($E10>=16,$E10<=25)),1,0)))+IFERROR(VLOOKUP($G10,'選定基準・配点'!$B$30:$C$32,2,FALSE),0)+IFERROR(VLOOKUP($H10,'選定基準・配点'!$B$34:$C$36,2,FALSE),0)+IFERROR(VLOOKUP($I10,'選定基準・配点'!$B$38:$C$41,2,FALSE),0)+IFERROR(VLOOKUP($K10,'選定基準・配点'!$B$43:$C$48,2,FALSE),0)) | M10: =IF($B10="","",IF($J10="恒常依存（除外）","除外",IF($L10>=12,"優先",IF($L10>=8,"要検討","見送り候補"))))
A11: 6 | L11: =IF($B11="","",IFERROR(VLOOKUP($C11,'選定基準・配点'!$B$21:$C$28,2,FALSE),0)+IF($E11="",0,IF(AND($E11>=5,$E11<=15),2,IF(OR(AND($E11>=3,$E11<=4),AND($E11>=16,$E11<=25)),1,0)))+IFERROR(VLOOKUP($G11,'選定基準・配点'!$B$30:$C$32,2,FALSE),0)+IFERROR(VLOOKUP($H11,'選定基準・配点'!$B$34:$C$36,2,FALSE),0)+IFERROR(VLOOKUP($I11,'選定基準・配点'!$B$38:$C$41,2,FALSE),0)+IFERROR(VLOOKUP($K11,'選定基準・配点'!$B$43:$C$48,2,FALSE),0)) | M11: =IF($B11="","",IF($J11="恒常依存（除外）","除外",IF($L11>=12,"優先",IF($L11>=8,"要検討","見送り候補"))))
A12: 7 | L12: =IF($B12="","",IFERROR(VLOOKUP($C12,'選定基準・配点'!$B$21:$C$28,2,FALSE),0)+IF($E12="",0,IF(AND($E12>=5,$E12<=15),2,IF(OR(AND($E12>=3,$E12<=4),AND($E12>=16,$E12<=25)),1,0)))+IFERROR(VLOOKUP($G12,'選定基準・配点'!$B$30:$C$32,2,FALSE),0)+IFERROR(VLOOKUP($H12,'選定基準・配点'!$B$34:$C$36,2,FALSE),0)+IFERROR(VLOOKUP($I12,'選定基準・配点'!$B$38:$C$41,2,FALSE),0)+IFERROR(VLOOKUP($K12,'選定基準・配点'!$B$43:$C$48,2,FALSE),0)) | M12: =IF($B12="","",IF($J12="恒常依存（除外）","除外",IF($L12>=12,"優先",IF($L12>=8,"要検討","見送り候補"))))
A13: 8 | L13: =IF($B13="","",IFERROR(VLOOKUP($C13,'選定基準・配点'!$B$21:$C$28,2,FALSE),0)+IF($E13="",0,IF(AND($E13>=5,$E13<=15),2,IF(OR(AND($E13>=3,$E13<=4),AND($E13>=16,$E13<=25)),1,0)))+IFERROR(VLOOKUP($G13,'選定基準・配点'!$B$30:$C$32,2,FALSE),0)+IFERROR(VLOOKUP($H13,'選定基準・配点'!$B$34:$C$36,2,FALSE),0)+IFERROR(VLOOKUP($I13,'選定基準・配点'!$B$38:$C$41,2,FALSE),0)+IFERROR(VLOOKUP($K13,'選定基準・配点'!$B$43:$C$48,2,FALSE),0)) | M13: =IF($B13="","",IF($J13="恒常依存（除外）","除外",IF($L13>=12,"優先",IF($L13>=8,"要検討","見送り候補"))))
A14: 9 | L14: =IF($B14="","",IFERROR(VLOOKUP($C14,'選定基準・配点'!$B$21:$C$28,2,FALSE),0)+IF($E14="",0,IF(AND($E14>=5,$E14<=15),2,IF(OR(AND($E14>=3,$E14<=4),AND($E14>=16,$E14<=25)),1,0)))+IFERROR(VLOOKUP($G14,'選定基準・配点'!$B$30:$C$32,2,FALSE),0)+IFERROR(VLOOKUP($H14,'選定基準・配点'!$B$34:$C$36,2,FALSE),0)+IFERROR(VLOOKUP($I14,'選定基準・配点'!$B$38:$C$41,2,FALSE),0)+IFERROR(VLOOKUP($K14,'選定基準・配点'!$B$43:$C$48,2,FALSE),0)) | M14: =IF($B14="","",IF($J14="恒常依存（除外）","除外",IF($L14>=12,"優先",IF($L14>=8,"要検討","見送り候補"))))
A15: 10 | L15: =IF($B15="","",IFERROR(VLOOKUP($C15,'選定基準・配点'!$B$21:$C$28,2,FALSE),0)+IF($E15="",0,IF(AND($E15>=5,$E15<=15),2,IF(OR(AND($E15>=3,$E15<=4),AND($E15>=16,$E15<=25)),1,0)))+IFERROR(VLOOKUP($G15,'選定基準・配点'!$B$30:$C$32,2,FALSE),0)+IFERROR(VLOOKUP($H15,'選定基準・配点'!$B$34:$C$36,2,FALSE),0)+IFERROR(VLOOKUP($I15,'選定基準・配点'!$B$38:$C$41,2,FALSE),0)+IFERROR(VLOOKUP($K15,'選定基準・配点'!$B$43:$C$48,2,FALSE),0)) | M15: =IF($B15="","",IF($J15="恒常依存（除外）","除外",IF($L15>=12,"優先",IF($L15>=8,"要検討","見送り候補"))))

Sheet 選定基準・配点
A1: ターゲット法人10社リスト｜選定基準・配点表
A2: 出所：法人ポジショニング.md（1.ペルソナ／適合サイン・除外条件・選定マトリクス）
A4: ■ 適合サイン（優先して入れる）
A5: ① Tier1業種：接客・飲食・宿・美容・介護・保育・式場（関係の質が接客品質と定着に直結）
A6: ② 5〜15名で、オーナー／店長／施設長が即決できる（1店舗・1施設で意思決定が完結）
A7: ③ 離職・採用難などの痛みが顕在（辞める・採用が追いつかない・ギスギス）
A8: ④ トップが長期雇用・育成志向（定着させたい意思がある）
A9: ⑤ 紹介経由でトップに直接届く接点がある
A11: ■ 除外条件（初期リストに入れない）
A12: ・スポットワーク／ギグ系（タイミー等）に恒常依存し、短期・入れ替わり前提で回している先
A13: 注：繁忙期の一時利用まで除外しない。外すのは“依存”しているケース。
A15: ■ 優先度スコアの見方（自動計算）
... A19: ■ 配点表（この表の数値を編集すると各行のスコアに反映されます）
A20: 項目 | B20: 選択肢 | C20: 配点
A21: 業種（Tier1） | B21: 飲食・カフェ | C21: 3
B22: 美容室・サロン | C22: 3
B23: 小規模宿 | C23: 3
B24: 介護・保育 | C24: 3
B25: 結婚式場 | C25: 3
B26: その他Tier1 | C26: 2
B27: Tier2（多店舗・宴会等） | C27: 1
B28: 対象外 | C28: 0
A30: 即決度 | B30: 即決可（トップ即決） | C30: 3
B31: 一部稟議 | C31: 1
B32: 稟議必要 | C32: 0
A34: 離職・採用の痛み | B34: 高（顕在） | C34: 3
B35: 中 | C35: 2
B36: 低 | C36: 0
A38: 長期雇用・育成志向 | B38: 強い | C38: 3
B39: 普通 | C39: 1
B40: 弱い | C40: 0
B41: 不明 | C41: 0
A43: 接点（経路） | B43: 紹介（トップ直） | C43: 3
B44: 紹介（担当者） | C44: 2
B45: 直接（コールド） | C45: 1
B46: LinkedIn | C46: 1
B47: イベント・交流会 | C47: 1
B48: 不明 | C48: 0
A50: スポットワーク依存 | B50: なし
B51: 一時的のみ
...
